<?xml version="1.0"?>
<robot name="kinova_kg3_finger" xmlns:xacro="http://ros.org/wiki/xacro">
	<property name="PKG" value=""/>
	<!--<property name="PKG" value="package://kinova_kg3/"/>-->
	<property name="M_PI" value="3.14159265358979"/>
	<property name="MESHLAB_SCALE" value="10.0"/>
	<xacro:macro name="kinova_kg3_finger" params="index origin_xx origin_yy origin_zz origin_r origin_p origin_y">  
		<joint name="jaco_joint_finger_${index}" type="revolute">
			<origin xyz="${origin_xx} ${origin_yy} ${origin_zz}" rpy="${origin_r} ${origin_p} ${origin_y}" />
			<parent link="jaco_link_hand" />
			<child link="jaco_link_finger_${index}" />
			<limit lower="0" upper="${50*M_PI/180}" effort="30" velocity="5"/>
			<axis xyz="0 0 1" />
	    </joint>

    	<link name="jaco_link_finger_${index}">
			<inertial>
			  <origin
				  xyz="${0.426520/MESHLAB_SCALE} ${-0.061351/MESHLAB_SCALE} ${0.000022/MESHLAB_SCALE}"
				rpy="0 0 0" />
			  <mass value="${0.021306/MESHLAB_SCALE}" />
		      <inertia
				  ixx="${0.000172/MESHLAB_SCALE/MESHLAB_SCALE}"
				  iyy="${0.001210/MESHLAB_SCALE/MESHLAB_SCALE}"
				  izz="${0.001179/MESHLAB_SCALE/MESHLAB_SCALE}"
				  ixy="${0.000012/MESHLAB_SCALE/MESHLAB_SCALE}"
				  ixz="${0.0/MESHLAB_SCALE/MESHLAB_SCALE}"
				  iyz="${0.0/MESHLAB_SCALE/MESHLAB_SCALE}" 
			  />
					</inertial>
			<visual>
			  <origin xyz="0 0 0" rpy="0 0 0" />
			  <geometry>
				  <mesh filename="${PKG}meshes/jaco_link_finger_2.STL" />
			  </geometry>
			  <material name="kinova_color">
				<color rgba="1 1 1 1" />
			  </material>
			</visual>
			<collision>
			  <origin xyz="0 0 0" rpy="0 0 0" />
			  <geometry>
				  <mesh filename="${PKG}meshes/jaco_link_finger_2.STL" />
			  </geometry>
			</collision>
	    </link>
	</xacro:macro>
</robot>

