<?xml version="1.0" ?>
<!-- =================================================================================== -->
<!-- |    This document was autogenerated by xacro from kinova_kg3.xacro               | -->
<!-- |    EDITING THIS FILE BY HAND IS NOT RECOMMENDED                                 | -->
<!-- =================================================================================== -->
<robot name="kinova_kg3" xmlns:xacro="http://ros.org/wiki/xacro">
  <!--
	   Little helper macro to define the inertia matrix needed
	   for links.
	   -->
  <!-- width is along x axis
	     length is along y axis
	     height is along z axis
	-->
  <!-- length is along the y-axis! -->
  <!--<property name="PKG" value="package://kinova_kg3/"/>-->
  <!--
	<link name="base_link">
		<visual>
			<origin xyz="0 0 0.5" rpy="0 0 0"/>
			<geometry>
				<box size="0.2 0.2 1"/>
			</geometry>
			<mass value="0.0"/>
			<xacro:cuboid_inertia_def width="0.2" length="0.2" height="1.0" mass="2"/> 
		</visual>
		<collision>
			<origin xyz="0 0 0.5" rpy="0 0 0"/>
			<geometry>
				<box size="0.2 0.2 1"/>
			</geometry>
		</collision>
	</link>

	<joint name="base_to_hand" type="fixed">
		<origin xyz="-0.1 0 0.9" rpy="0 ${-90*M_PI/180} 0"/>
		<parent link="base_link"/>
		<child link="jaco_link_hand"/>
	</joint>
-->
  <link name="jaco_link_hand">
    <inertial>
      <origin rpy="0 0 0" xyz="-0.0002375 0.0041767 0.0758896"/>
      <!--<mass value="${0.121620/MESHLAB_SCALE/MESHLAB_SCALE}"/>-->
      <mass value="0.0"/>
      <inertia ixx="0.00021528" ixy="1e-08" ixz="-6e-08" iyy="0.00018751" iyz="-1.43e-06" izz="0.00015785"/>
    </inertial>
    <visual>
      <origin rpy="0 0 0" xyz="0 0 0"/>
      <geometry>
        <mesh filename="meshes/jaco_link_hand.STL"/>
      </geometry>
      <material name="">
        <color rgba="0.752941176470588 0.752941176470588 0.752941176470588 1"/>
      </material>
    </visual>
    <collision>
      <origin rpy="0 0 0" xyz="0 0 0"/>
      <geometry>
        <mesh filename="meshes/jaco_link_hand_collision.STL"/>
      </geometry>
    </collision>
  </link>
  <!--<property name="PKG" value="package://kinova_kg3/"/>-->
  <joint name="jaco_joint_finger_1" type="revolute">
    <origin rpy="1.57925286601 -0.980344825914 -1.60227019088" xyz="0.00228309324473 -0.0312566848706 0.114430431187"/>
    <parent link="jaco_link_hand"/>
    <child link="jaco_link_finger_1"/>
    <limit effort="30" lower="0" upper="0.872664625997" velocity="5"/>
    <axis xyz="0 0 1"/>
  </joint>
  <link name="jaco_link_finger_1">
    <inertial>
      <origin rpy="0 0 0" xyz="0.042652 -0.0061351 2.2e-06"/>
      <mass value="0.0021306"/>
      <inertia ixx="1.72e-06" ixy="1.2e-07" ixz="0.0" iyy="1.21e-05" iyz="0.0" izz="1.179e-05"/>
    </inertial>
    <visual>
      <origin rpy="0 0 0" xyz="0 0 0"/>
      <geometry>
        <mesh filename="meshes/jaco_link_finger_2.STL"/>
      </geometry>
      <material name="kinova_color">
        <color rgba="1 1 1 1"/>
      </material>
    </visual>
    <collision>
      <origin rpy="0 0 0" xyz="0 0 0"/>
      <geometry>
        <mesh filename="meshes/jaco_link_finger_2_collision.STL"/>
      </geometry>
    </collision>
  </link>
  <joint name="jaco_joint_finger_2" type="revolute">
    <origin rpy="1.56248404081 -0.979964587179 1.39416913027" xyz="0.021684484967 0.0270991446492 0.114669378847"/>
    <parent link="jaco_link_hand"/>
    <child link="jaco_link_finger_2"/>
    <limit effort="30" lower="0" upper="0.872664625997" velocity="5"/>
    <axis xyz="0 0 1"/>
  </joint>
  <link name="jaco_link_finger_2">
    <inertial>
      <origin rpy="0 0 0" xyz="0.042652 -0.0061351 2.2e-06"/>
      <mass value="0.0021306"/>
      <inertia ixx="1.72e-06" ixy="1.2e-07" ixz="0.0" iyy="1.21e-05" iyz="0.0" izz="1.179e-05"/>
    </inertial>
    <visual>
      <origin rpy="0 0 0" xyz="0 0 0"/>
      <geometry>
        <mesh filename="meshes/jaco_link_finger_2.STL"/>
      </geometry>
      <material name="kinova_color">
        <color rgba="1 1 1 1"/>
      </material>
    </visual>
    <collision>
      <origin rpy="0 0 0" xyz="0 0 0"/>
      <geometry>
        <mesh filename="meshes/jaco_link_finger_2_collision.STL"/>
      </geometry>
    </collision>
  </link>
  <joint name="jaco_joint_finger_3" type="revolute">
    <origin rpy="1.56250901308 -0.978234931608 1.76352902216" xyz="-0.0228265816405 0.0270473381757 0.114459755558"/>
    <parent link="jaco_link_hand"/>
    <child link="jaco_link_finger_3"/>
    <limit effort="30" lower="0" upper="0.872664625997" velocity="5"/>
    <axis xyz="0 0 1"/>
  </joint>
  <link name="jaco_link_finger_3">
    <inertial>
      <origin rpy="0 0 0" xyz="0.042652 -0.0061351 2.2e-06"/>
      <mass value="0.0021306"/>
      <inertia ixx="1.72e-06" ixy="1.2e-07" ixz="0.0" iyy="1.21e-05" iyz="0.0" izz="1.179e-05"/>
    </inertial>
    <visual>
      <origin rpy="0 0 0" xyz="0 0 0"/>
      <geometry>
        <mesh filename="meshes/jaco_link_finger_2.STL"/>
      </geometry>
      <material name="kinova_color">
        <color rgba="1 1 1 1"/>
      </material>
    </visual>
    <collision>
      <origin rpy="0 0 0" xyz="0 0 0"/>
      <geometry>
        <mesh filename="meshes/jaco_link_finger_2_collision.STL"/>
      </geometry>
    </collision>
  </link>
</robot>

